2016-11-11 10:22:27,291 [Thread-6:9112] [django.request:152] [WARNING]- Not Found: /favicon.ico
2016-11-11 10:46:15,653 [Thread-9:9960] [django.request:152] [WARNING]- Not Found: /
2016-11-11 19:58:04,434 [Thread-28:8664] [django.request:152] [WARNING]- Not Found: /favicon.ico
2016-11-14 09:53:22,696 [Thread-18:5228] [django.request:152] [WARNING]- Not Found: /favicon.ico
2016-11-14 11:00:00,341 [Thread-19:10664] [django.request:124] [ERROR]- Internal Server Error: /admin/polls/commonlyusedmodel/add/
Traceback (most recent call last):
  File "C:\Python35\lib\site-packages\django\db\backends\utils.py", line 64, in execute
    return self.cursor.execute(sql, params)
  File "C:\Python35\lib\site-packages\django\db\backends\sqlite3\base.py", line 337, in execute
    return Database.Cursor.execute(self, query, params)
sqlite3.IntegrityError: NOT NULL constraint failed: app_largetable.f2

The above exception was the direct cause of the following exception:

Traceback (most recent call last):
  File "C:\Python35\lib\site-packages\django\core\handlers\exception.py", line 39, in inner
    response = get_response(request)
  File "C:\Python35\lib\site-packages\django\core\handlers\base.py", line 187, in _get_response
    response = self.process_exception_by_middleware(e, request)
  File "C:\Python35\lib\site-packages\django\core\handlers\base.py", line 185, in _get_response
    response = wrapped_callback(request, *callback_args, **callback_kwargs)
  File "C:\Python35\lib\site-packages\django\contrib\admin\options.py", line 544, in wrapper
    return self.admin_site.admin_view(view)(*args, **kwargs)
  File "C:\Python35\lib\site-packages\django\utils\decorators.py", line 149, in _wrapped_view
    response = view_func(request, *args, **kwargs)
  File "C:\Python35\lib\site-packages\django\views\decorators\cache.py", line 57, in _wrapped_view_func
    response = view_func(request, *args, **kwargs)
  File "C:\Python35\lib\site-packages\django\contrib\admin\sites.py", line 211, in inner
    return view(request, *args, **kwargs)
  File "C:\Python35\lib\site-packages\django\contrib\admin\options.py", line 1509, in add_view
    return self.changeform_view(request, None, form_url, extra_context)
  File "C:\Python35\lib\site-packages\django\utils\decorators.py", line 67, in _wrapper
    return bound_func(*args, **kwargs)
  File "C:\Python35\lib\site-packages\django\utils\decorators.py", line 149, in _wrapped_view
    response = view_func(request, *args, **kwargs)
  File "C:\Python35\lib\site-packages\django\utils\decorators.py", line 63, in bound_func
    return func.__get__(self, type(self))(*args2, **kwargs2)
  File "C:\Python35\lib\contextlib.py", line 30, in inner
    return func(*args, **kwds)
  File "C:\Python35\lib\site-packages\django\contrib\admin\options.py", line 1449, in changeform_view
    self.save_model(request, new_object, form, not add)
  File "C:\Python35\lib\site-packages\django\contrib\admin\options.py", line 1007, in save_model
    obj.save()
  File "C:\Python35\lib\site-packages\django\db\models\base.py", line 796, in save
    force_update=force_update, update_fields=update_fields)
  File "C:\Python35\lib\site-packages\django\db\models\base.py", line 824, in save_base
    updated = self._save_table(raw, cls, force_insert, force_update, using, update_fields)
  File "C:\Python35\lib\site-packages\django\db\models\base.py", line 908, in _save_table
    result = self._do_insert(cls._base_manager, using, fields, update_pk, raw)
  File "C:\Python35\lib\site-packages\django\db\models\base.py", line 947, in _do_insert
    using=using, raw=raw)
  File "C:\Python35\lib\site-packages\django\db\models\manager.py", line 85, in manager_method
    return getattr(self.get_queryset(), name)(*args, **kwargs)
  File "C:\Python35\lib\site-packages\django\db\models\query.py", line 1045, in _insert
    return query.get_compiler(using=using).execute_sql(return_id)
  File "C:\Python35\lib\site-packages\django\db\models\sql\compiler.py", line 1054, in execute_sql
    cursor.execute(sql, params)
  File "C:\Python35\lib\site-packages\debug_toolbar\panels\sql\tracking.py", line 159, in execute
    return self._record(self.cursor.execute, sql, params)
  File "C:\Python35\lib\site-packages\debug_toolbar\panels\sql\tracking.py", line 101, in _record
    return method(sql, params)
  File "C:\Python35\lib\site-packages\django\db\backends\utils.py", line 79, in execute
    return super(CursorDebugWrapper, self).execute(sql, params)
  File "C:\Python35\lib\site-packages\django\db\backends\utils.py", line 64, in execute
    return self.cursor.execute(sql, params)
  File "C:\Python35\lib\site-packages\django\db\utils.py", line 94, in __exit__
    six.reraise(dj_exc_type, dj_exc_value, traceback)
  File "C:\Python35\lib\site-packages\django\utils\six.py", line 685, in reraise
    raise value.with_traceback(tb)
  File "C:\Python35\lib\site-packages\django\db\backends\utils.py", line 64, in execute
    return self.cursor.execute(sql, params)
  File "C:\Python35\lib\site-packages\django\db\backends\sqlite3\base.py", line 337, in execute
    return Database.Cursor.execute(self, query, params)
django.db.utils.IntegrityError: NOT NULL constraint failed: app_largetable.f2
2016-11-14 11:00:03,921 [Thread-21:7016] [django.request:124] [ERROR]- Internal Server Error: /admin/polls/commonlyusedmodel/add/
Traceback (most recent call last):
  File "C:\Python35\lib\site-packages\django\db\backends\utils.py", line 64, in execute
    return self.cursor.execute(sql, params)
  File "C:\Python35\lib\site-packages\django\db\backends\sqlite3\base.py", line 337, in execute
    return Database.Cursor.execute(self, query, params)
sqlite3.IntegrityError: NOT NULL constraint failed: app_largetable.f2

The above exception was the direct cause of the following exception:

Traceback (most recent call last):
  File "C:\Python35\lib\site-packages\django\core\handlers\exception.py", line 39, in inner
    response = get_response(request)
  File "C:\Python35\lib\site-packages\django\core\handlers\base.py", line 187, in _get_response
    response = self.process_exception_by_middleware(e, request)
  File "C:\Python35\lib\site-packages\django\core\handlers\base.py", line 185, in _get_response
    response = wrapped_callback(request, *callback_args, **callback_kwargs)
  File "C:\Python35\lib\site-packages\django\contrib\admin\options.py", line 544, in wrapper
    return self.admin_site.admin_view(view)(*args, **kwargs)
  File "C:\Python35\lib\site-packages\django\utils\decorators.py", line 149, in _wrapped_view
    response = view_func(request, *args, **kwargs)
  File "C:\Python35\lib\site-packages\django\views\decorators\cache.py", line 57, in _wrapped_view_func
    response = view_func(request, *args, **kwargs)
  File "C:\Python35\lib\site-packages\django\contrib\admin\sites.py", line 211, in inner
    return view(request, *args, **kwargs)
  File "C:\Python35\lib\site-packages\django\contrib\admin\options.py", line 1509, in add_view
    return self.changeform_view(request, None, form_url, extra_context)
  File "C:\Python35\lib\site-packages\django\utils\decorators.py", line 67, in _wrapper
    return bound_func(*args, **kwargs)
  File "C:\Python35\lib\site-packages\django\utils\decorators.py", line 149, in _wrapped_view
    response = view_func(request, *args, **kwargs)
  File "C:\Python35\lib\site-packages\django\utils\decorators.py", line 63, in bound_func
    return func.__get__(self, type(self))(*args2, **kwargs2)
  File "C:\Python35\lib\contextlib.py", line 30, in inner
    return func(*args, **kwds)
  File "C:\Python35\lib\site-packages\django\contrib\admin\options.py", line 1449, in changeform_view
    self.save_model(request, new_object, form, not add)
  File "C:\Python35\lib\site-packages\django\contrib\admin\options.py", line 1007, in save_model
    obj.save()
  File "C:\Python35\lib\site-packages\django\db\models\base.py", line 796, in save
    force_update=force_update, update_fields=update_fields)
  File "C:\Python35\lib\site-packages\django\db\models\base.py", line 824, in save_base
    updated = self._save_table(raw, cls, force_insert, force_update, using, update_fields)
  File "C:\Python35\lib\site-packages\django\db\models\base.py", line 908, in _save_table
    result = self._do_insert(cls._base_manager, using, fields, update_pk, raw)
  File "C:\Python35\lib\site-packages\django\db\models\base.py", line 947, in _do_insert
    using=using, raw=raw)
  File "C:\Python35\lib\site-packages\django\db\models\manager.py", line 85, in manager_method
    return getattr(self.get_queryset(), name)(*args, **kwargs)
  File "C:\Python35\lib\site-packages\django\db\models\query.py", line 1045, in _insert
    return query.get_compiler(using=using).execute_sql(return_id)
  File "C:\Python35\lib\site-packages\django\db\models\sql\compiler.py", line 1054, in execute_sql
    cursor.execute(sql, params)
  File "C:\Python35\lib\site-packages\debug_toolbar\panels\sql\tracking.py", line 159, in execute
    return self._record(self.cursor.execute, sql, params)
  File "C:\Python35\lib\site-packages\debug_toolbar\panels\sql\tracking.py", line 101, in _record
    return method(sql, params)
  File "C:\Python35\lib\site-packages\django\db\backends\utils.py", line 79, in execute
    return super(CursorDebugWrapper, self).execute(sql, params)
  File "C:\Python35\lib\site-packages\django\db\backends\utils.py", line 64, in execute
    return self.cursor.execute(sql, params)
  File "C:\Python35\lib\site-packages\django\db\utils.py", line 94, in __exit__
    six.reraise(dj_exc_type, dj_exc_value, traceback)
  File "C:\Python35\lib\site-packages\django\utils\six.py", line 685, in reraise
    raise value.with_traceback(tb)
  File "C:\Python35\lib\site-packages\django\db\backends\utils.py", line 64, in execute
    return self.cursor.execute(sql, params)
  File "C:\Python35\lib\site-packages\django\db\backends\sqlite3\base.py", line 337, in execute
    return Database.Cursor.execute(self, query, params)
django.db.utils.IntegrityError: NOT NULL constraint failed: app_largetable.f2
2016-11-14 11:00:10,337 [Thread-25:8572] [django.request:124] [ERROR]- Internal Server Error: /admin/polls/commonlyusedmodel/add/
Traceback (most recent call last):
  File "C:\Python35\lib\site-packages\django\db\backends\utils.py", line 64, in execute
    return self.cursor.execute(sql, params)
  File "C:\Python35\lib\site-packages\django\db\backends\sqlite3\base.py", line 337, in execute
    return Database.Cursor.execute(self, query, params)
sqlite3.IntegrityError: NOT NULL constraint failed: app_largetable.f2

The above exception was the direct cause of the following exception:

Traceback (most recent call last):
  File "C:\Python35\lib\site-packages\django\core\handlers\exception.py", line 39, in inner
    response = get_response(request)
  File "C:\Python35\lib\site-packages\django\core\handlers\base.py", line 187, in _get_response
    response = self.process_exception_by_middleware(e, request)
  File "C:\Python35\lib\site-packages\django\core\handlers\base.py", line 185, in _get_response
    response = wrapped_callback(request, *callback_args, **callback_kwargs)
  File "C:\Python35\lib\site-packages\django\contrib\admin\options.py", line 544, in wrapper
    return self.admin_site.admin_view(view)(*args, **kwargs)
  File "C:\Python35\lib\site-packages\django\utils\decorators.py", line 149, in _wrapped_view
    response = view_func(request, *args, **kwargs)
  File "C:\Python35\lib\site-packages\django\views\decorators\cache.py", line 57, in _wrapped_view_func
    response = view_func(request, *args, **kwargs)
  File "C:\Python35\lib\site-packages\django\contrib\admin\sites.py", line 211, in inner
    return view(request, *args, **kwargs)
  File "C:\Python35\lib\site-packages\django\contrib\admin\options.py", line 1509, in add_view
    return self.changeform_view(request, None, form_url, extra_context)
  File "C:\Python35\lib\site-packages\django\utils\decorators.py", line 67, in _wrapper
    return bound_func(*args, **kwargs)
  File "C:\Python35\lib\site-packages\django\utils\decorators.py", line 149, in _wrapped_view
    response = view_func(request, *args, **kwargs)
  File "C:\Python35\lib\site-packages\django\utils\decorators.py", line 63, in bound_func
    return func.__get__(self, type(self))(*args2, **kwargs2)
  File "C:\Python35\lib\contextlib.py", line 30, in inner
    return func(*args, **kwds)
  File "C:\Python35\lib\site-packages\django\contrib\admin\options.py", line 1449, in changeform_view
    self.save_model(request, new_object, form, not add)
  File "C:\Python35\lib\site-packages\django\contrib\admin\options.py", line 1007, in save_model
    obj.save()
  File "C:\Python35\lib\site-packages\django\db\models\base.py", line 796, in save
    force_update=force_update, update_fields=update_fields)
  File "C:\Python35\lib\site-packages\django\db\models\base.py", line 824, in save_base
    updated = self._save_table(raw, cls, force_insert, force_update, using, update_fields)
  File "C:\Python35\lib\site-packages\django\db\models\base.py", line 908, in _save_table
    result = self._do_insert(cls._base_manager, using, fields, update_pk, raw)
  File "C:\Python35\lib\site-packages\django\db\models\base.py", line 947, in _do_insert
    using=using, raw=raw)
  File "C:\Python35\lib\site-packages\django\db\models\manager.py", line 85, in manager_method
    return getattr(self.get_queryset(), name)(*args, **kwargs)
  File "C:\Python35\lib\site-packages\django\db\models\query.py", line 1045, in _insert
    return query.get_compiler(using=using).execute_sql(return_id)
  File "C:\Python35\lib\site-packages\django\db\models\sql\compiler.py", line 1054, in execute_sql
    cursor.execute(sql, params)
  File "C:\Python35\lib\site-packages\debug_toolbar\panels\sql\tracking.py", line 159, in execute
    return self._record(self.cursor.execute, sql, params)
  File "C:\Python35\lib\site-packages\debug_toolbar\panels\sql\tracking.py", line 101, in _record
    return method(sql, params)
  File "C:\Python35\lib\site-packages\django\db\backends\utils.py", line 79, in execute
    return super(CursorDebugWrapper, self).execute(sql, params)
  File "C:\Python35\lib\site-packages\django\db\backends\utils.py", line 64, in execute
    return self.cursor.execute(sql, params)
  File "C:\Python35\lib\site-packages\django\db\utils.py", line 94, in __exit__
    six.reraise(dj_exc_type, dj_exc_value, traceback)
  File "C:\Python35\lib\site-packages\django\utils\six.py", line 685, in reraise
    raise value.with_traceback(tb)
  File "C:\Python35\lib\site-packages\django\db\backends\utils.py", line 64, in execute
    return self.cursor.execute(sql, params)
  File "C:\Python35\lib\site-packages\django\db\backends\sqlite3\base.py", line 337, in execute
    return Database.Cursor.execute(self, query, params)
django.db.utils.IntegrityError: NOT NULL constraint failed: app_largetable.f2
